// função que gera um número aleatório
const generateRandomNumber = () => Math.round(Math.random() * 10);

// promise resolvida retornando o número aleatório
const resolvedPromise = () =>
  new Promise((resolve, reject) => {
    setTimeout(() => {
      const randomNumber = generateRandomNumber();
      resolve(randomNumber);
    }, 1000);
  });

// promise rejeitada retornando um objeto de erro
const rejectedPromise = () =>
  new Promise((resolve, reject) => {
    setTimeout(() => {
      const randomNumber = generateRandomNumber();
      reject(new Error(`O número ${randomNumber} é inválido.`));
    }, 1000);
  });

// resolvedPromise()
//   .then((response) => {
//     console.log(`resolvedPromise: o número gerado é ${response}.`);
//   })
//   .catch((error) => {
//     console.log(`Com a promise resolvida, não irá passar pelo catch`);
//   });

// rejectedPromise()
//   .then((response) => {
//     console.log(`Com a promise rejeitada, não irá passar pelo then`);
//   })
//   .catch((error) => {
//     console.log(`rejectedPromise: ${error.message}`);
//   });


randomPromise = () =>
  new Promise((resolve, reject) => {
    setTimeout(() => {
      const randomNumber = generateRandomNumber();
      randomNumber % 2 === 0 ? resolve(randomNumber) : reject(new Error('O número não é válido'))
    }, 1000)
  })

randomPromise()
  .then((response) => {
    console.log(`Resolvida: ${response}`)
  })
  .catch((error) => {
    console.log(`Rejeitada: ${error}`)
  })